<?xml version="1.0" ?>
<!-- =================================================================================== -->
<!-- |    This document was autogenerated by xacro from urdf/xacro/rover.urdf.xacro    | -->
<!-- |    EDITING THIS FILE BY HAND IS NOT RECOMMENDED                                 | -->
<!-- =================================================================================== -->
<robot name="rover">
  <!-- épaisseur roue -->
  <!-- châssis -->
  <link name="base_link">
    <visual>
      <origin xyz="0 0 0.1"/>
      <geometry>
        <box size="0.6 0.4 0.2"/>
      </geometry>
      <material name="gray">
        <color rgba="0.2 0.2 0.2 1"/>
      </material>
    </visual>
    <collision>
      <origin xyz="0 0 0.1"/>
      <geometry>
        <box size="0.6 0.4 0.2"/>
      </geometry>
    </collision>
    <inertial>
      <mass value="8.0"/>
      <origin xyz="0 0 0.1"/>
      <inertia ixx="0.2" ixy="0" ixz="0" iyy="0.2" iyz="0" izz="0.2"/>
    </inertial>
  </link>
  <link name="wheel_fl">
    <visual>
      <origin rpy="1.5708 0 0" xyz="0 0 0"/>
      <geometry>
        <cylinder length="0.05" radius="0.09"/>
      </geometry>
      <material name="black">
        <color rgba="0.05 0.05 0.05 1"/>
      </material>
    </visual>
    <collision>
      <origin rpy="1.5708 0 0" xyz="0 0 0"/>
      <geometry>
        <cylinder length="0.05" radius="0.09"/>
      </geometry>
    </collision>
    <inertial>
      <mass value="0.3"/>
      <inertia ixx="0.001" ixy="0" ixz="0" iyy="0.001" iyz="0" izz="0.001"/>
    </inertial>
  </link>
  <joint name="wheel_fl_joint" type="revolute">
    <parent link="base_link"/>
    <child link="wheel_fl"/>
    <origin xyz="0.21 0.17500000000000002 0.09"/>
    <axis xyz="0 1 0"/>
    <limit effort="10" lower="-3.14" upper="3.14" velocity="20"/>
  </joint>
  <link name="wheel_fr">
    <visual>
      <origin rpy="1.5708 0 0" xyz="0 0 0"/>
      <geometry>
        <cylinder length="0.05" radius="0.09"/>
      </geometry>
      <material name="black">
        <color rgba="0.05 0.05 0.05 1"/>
      </material>
    </visual>
    <collision>
      <origin rpy="1.5708 0 0" xyz="0 0 0"/>
      <geometry>
        <cylinder length="0.05" radius="0.09"/>
      </geometry>
    </collision>
    <inertial>
      <mass value="0.3"/>
      <inertia ixx="0.001" ixy="0" ixz="0" iyy="0.001" iyz="0" izz="0.001"/>
    </inertial>
  </link>
  <joint name="wheel_fr_joint" type="revolute">
    <parent link="base_link"/>
    <child link="wheel_fr"/>
    <origin xyz="0.21 -0.17500000000000002 0.09"/>
    <axis xyz="0 1 0"/>
    <limit effort="10" lower="-3.14" upper="3.14" velocity="20"/>
  </joint>
  <link name="wheel_rl">
    <visual>
      <origin rpy="1.5708 0 0" xyz="0 0 0"/>
      <geometry>
        <cylinder length="0.05" radius="0.09"/>
      </geometry>
      <material name="black">
        <color rgba="0.05 0.05 0.05 1"/>
      </material>
    </visual>
    <collision>
      <origin rpy="1.5708 0 0" xyz="0 0 0"/>
      <geometry>
        <cylinder length="0.05" radius="0.09"/>
      </geometry>
    </collision>
    <inertial>
      <mass value="0.3"/>
      <inertia ixx="0.001" ixy="0" ixz="0" iyy="0.001" iyz="0" izz="0.001"/>
    </inertial>
  </link>
  <joint name="wheel_rl_joint" type="revolute">
    <parent link="base_link"/>
    <child link="wheel_rl"/>
    <origin xyz="-0.21 0.17500000000000002 0.09"/>
    <axis xyz="0 1 0"/>
    <limit effort="10" lower="-3.14" upper="3.14" velocity="20"/>
  </joint>
  <link name="wheel_rr">
    <visual>
      <origin rpy="1.5708 0 0" xyz="0 0 0"/>
      <geometry>
        <cylinder length="0.05" radius="0.09"/>
      </geometry>
      <material name="black">
        <color rgba="0.05 0.05 0.05 1"/>
      </material>
    </visual>
    <collision>
      <origin rpy="1.5708 0 0" xyz="0 0 0"/>
      <geometry>
        <cylinder length="0.05" radius="0.09"/>
      </geometry>
    </collision>
    <inertial>
      <mass value="0.3"/>
      <inertia ixx="0.001" ixy="0" ixz="0" iyy="0.001" iyz="0" izz="0.001"/>
    </inertial>
  </link>
  <joint name="wheel_rr_joint" type="revolute">
    <parent link="base_link"/>
    <child link="wheel_rr"/>
    <origin xyz="-0.21 -0.17500000000000002 0.09"/>
    <axis xyz="0 1 0"/>
    <limit effort="10" lower="-3.14" upper="3.14" velocity="20"/>
  </joint>
</robot>
